Workbook

Sheet 0 Portada
B2: IES
B3: Intelligent Electronic Solutions
B5: INFORME DE GESTIÓN DE PROCESOS CONTABLES
B6: Carga planificada, ocupación por posición y seguimiento mensual · 2026
B9: CONTROL DEL DOCUMENTO
B10: Código | C10: IES-CT-INF-001
B11: Versión | C11: 1.0
B12: Fecha de emisión | C12: 10 de agosto de 2026
B13: Elaborado por | C13: Cristian Bernal — Contador
B14: Dirigido a | C14: Gerencia · Supervisión · Recursos Humanos
B15: Periodicidad | C15: Mensual, con corte al cierre de cada mes
B16: Fuente de datos | C16: Aplicación IES de seguimiento de procesos contables
B17: Alcance | C17: Ciclo contable mensual — cinco posiciones del proceso
B20: CONTENIDO
B21: 1 Resumen | C21: Carga anual por persona y concentración de la carga dentro del mes
B22: 2 Ocupacion | C22: Días-tarea de cada posición en los doce meses del año
B23: 3 Calendario | C23: Hitos del ciclo con fecha límite y nivel de criticidad
B24: 4 Gestion mensual | C24: Formato de seguimiento del cumplimiento real, mes a mes
B25: 5 Consolidado | C25: Resumen anual del cumplimiento, se alimenta de la hoja 4
B28: NOTA METODOLÓGICA
B29: · Días-tarea: suma de los días que cada tarea permanece abierta en el mes. Mide exposición y simultaneidad, no horas trabajadas.
B30: · Ocupación: porcentaje de días del período con al menos una tarea abierta.
B31: · Pico: máximo de tareas de una misma persona abiertas en un mismo día.
B32: · Las hojas 1, 2 y 3 reflejan la carga PLANIFICADA según el catálogo de procesos.
B33: · La hoja 4 registra la EJECUCIÓN real y se diligencia al cierre de cada mes.

Sheet 1 Resumen
A1: IES | B1: Informe de Procesos Contables · 2026
B2: Resumen ejecutivo para Gerencia · Intelligent Electronic Solutions
B4: CARGA PLANIFICADA DEL AÑO
B5: Persona | C5: Cargo | D5: Tareas al año | E5: Días-tarea al año | F5: Ocupación | G5: Tareas/día promedio | H5: Pico
B6: Isnardi Sanches | C6: Tesorera | D6: 72 | E6: 1196 | F6: 1 | G6: 3.28 | H6: 5
B7: Luis Amador | C7: Aux. Contable | D7: 120 | E7: 1003 | F7: 1 | G7: 2.75 | H7: 4
B8: Cristian Bernal | C8: Contador | D8: 174 | E8: 719 | F8: 1 | G8: 1.97 | H8: 7
B9: Beatriz | C9: Insumos Facturación | D9: 24 | E9: 401 | F9: 1 | G9: 1.1 | H9: 2
B10: Edgar Metaute | C10: Automatización / Siigo | D10: 60 | E10: 269 | F10: 0.57260274 | G10: 0.74 | H10: 2
B13: CONCENTRACIÓN DE LA CARGA EN EL MES
B14: Tramo del mes | C14: Días-tarea | D14: Peso | E14: Lectura
B15: Días 1 a 7 | C15: 63 | D15: 0.20930233 | E15: Apertura del mes y facturación
B16: Días 8 a 14 | C16: 90 | D16: 0.29900332 | E16: Cierre contable e insumos del informe
B17: Días 15 a 21 | C17: 54 | D17: 0.17940199 | E17: Entrega a Gerencia, socios y RADIAN
B18: Días 22 a 28 | C18: 64 | D18: 0.21262458 | E18: Causaciones y nómina de segunda quincena
B19: Días 29 al cierre | C19: 30 | D19: 0.099667774 | E19: Desembolsos y archivo plano
B20: TOTAL | C20: 301 | D20: 1
B23: HALLAZGOS
B24: Concentración | C24: El 30% de la carga del mes cae entre los días 8 y 14. Coincide con el cierre contable y con los cinco insumos del informe.
B25: Pico del equipo | C25: 15 tareas simultáneas del equipo el día 10, 12, 13. Es el punto más tenso del ciclo.
B26: Contaduría | C26: Pico de 7 tareas propias en un mismo día. Es la posición con la ventana más apretada del mes.
B27: Tesorería | C27: Ocupación del 100%: tiene tareas abiertas todos los días del año por el registro diario de RC y RP.
B28: Gerencia | C28: Dos compromisos con fecha: definir viáticos de tarjeta (días 6 a 10) y dar feedback al informe (días 13 a 14).

Sheet 2 Ocupacion
A1: IES | B1: Nivel de ocupación mes a mes
B2: Días-tarea planificados por persona · 2026
B4: DÍAS-TAREA POR MES
B5: Persona | C5: Ene | D5: Feb | E5: Mar | F5: Abr | G5: May | H5: Jun | I5: Jul | J5: Ago | K5: Sep | L5: Oct | M5: Nov | N5: Dic | O5: Año
B6: Isnardi | C6: 102 | D6: 90 | E6: 102 | F6: 98 | G6: 102 | H6: 98 | I6: 102 | J6: 102 | K6: 98 | L6: 102 | M6: 98 | N6: 102 | O6: 1196
B7: Luis | C7: 85 | D7: 76 | E7: 85 | F7: 83 | G7: 85 | H7: 83 | I7: 85 | J7: 85 | K7: 83 | L7: 85 | M7: 83 | N7: 85 | O7: 1003
B8: Cristian | C8: 64 | D8: 54 | E8: 64 | F8: 56 | G8: 64 | H8: 56 | I8: 64 | J8: 57 | K8: 63 | L8: 57 | M8: 63 | N8: 57 | O8: 719
B9: Beatriz | C9: 34 | D9: 31 | E9: 34 | F9: 33 | G9: 34 | H9: 33 | I9: 34 | J9: 34 | K9: 33 | L9: 34 | M9: 33 | N9: 34 | O9: 401
B10: Edgar | C10: 23 | D10: 20 | E10: 23 | F10: 22 | G10: 23 | H10: 22 | I10: 23 | J10: 23 | K10: 22 | L10: 23 | M10: 22 | N10: 23 | O10: 269
B11: EQUIPO | C11: 308 | D11: 271 | E11: 308 | F11: 292 | G11: 308 | H11: 292 | I11: 308 | J11: 301 | K11: 299 | L11: 301 | M11: 299 | N11: 301 | O11: 3588
B14: OCUPACIÓN Y PICO POR PERSONA
B15: Persona | C15: Tareas mes tipo | D15: Días con tarea abierta | E15: Ocupación del mes | F15: Tareas/día promedio | G15: Pico del mes | H15: Días del pico
B16: Isnardi Sanches | C16: 6 | D16: 31 de 31 | E16: 1 | F16: 3.29 | G16: 5 | H16: 14, 15
B17: Luis Amador | C17: 10 | D17: 31 de 31 | E17: 1 | F17: 2.74 | G17: 4 | H17: 10, 25, 26, 27, 28, 29
B18: Cristian Bernal | C18: 14 | D18: 31 de 31 | E18: 1 | F18: 1.84 | G18: 7 | H18: 12
B19: Beatriz | C19: 2 | D19: 31 de 31 | E19: 1 | F19: 1.1 | G19: 2 | H19: 10, 11, 12
B20: Edgar Metaute | C20: 5 | D20: 18 de 31 | E20: 0.58064516 | F20: 0.74 | G20: 2 | H20: 1, 2, 3, 4, 5
B23: Días-tarea: suma de los días que cada tarea permanece abierta. Mide exposición, no horas trabajadas.
B24: Pico: máximo de tareas de esa persona abiertas en un mismo día. Verde hasta 3, ámbar 4 y 5, rojo desde 6.

Sheet 3 Calendario
A1: IES | B1: Calendario del ciclo mensual
B2: Hitos con fecha comprometida · aplica todos los meses
B4: Días | C4: Responsable | D4: Hito | E4: Fecha límite | F4: Criticidad
B5: 1 al 5 | C5: Edgar Metaute | D5: Emisión de facturas electrónicas | E5: Día 5 | F5: Alta
B6: 3 al 9 | C6: Luis Amador | D6: Conciliación bancaria | E6: Día 9 | F6: Media
B7: 6 al 10 | C7: Luis + Edgar | D7: Conciliación de tarjeta y definición de viáticos | E7: Día 10 | F7: Alta
B8: 10 al 13 | C8: Luis Amador | D8: Causación de seguridad social | E8: Día 13 | F8: Legal
B9: 10 al 14 | C9: Luis Amador | D9: Causación de nómina primera quincena | E9: Día 14 | F9: Legal
B10: 10 al 14 | C10: Cristian Bernal | D10: Cierre contable y retención en la fuente | E10: Día 14 | F10: Legal
B11: 9 al 13 | C11: Cristian Bernal | D11: Insumos del informe: flujo, cartera, recaudo, EESF, ER | E11: Día 13 | F11: Alta
B12: 10 al 12 | C12: Beatriz | D12: Comentarios comerciales al informe | E12: Día 12 | F12: Media
B13: 13 al 15 | C13: Isnardi Sanches | D13: Pago de seguridad social | E13: Día 15 | F13: Legal
B14: 13 al 14 | C14: Edgar Metaute | D14: Feedback del informe antes de socios | E14: Día 14 | F14: Alta
B15: 14 al 16 | C15: Isnardi Sanches | D15: Desembolso de nómina primera quincena | E15: Día 16 | F15: Legal
... B22: 29 al cierre | C22: Isnardi Sanches | D22: Desembolso de nómina segunda quincena | E22: Cierre | F22: Legal
B25: Legal: tiene vencimiento de ley, no admite aplazamiento.
B26: Alta: si se retrasa, frena a otra persona del equipo.
B27: Media: afecta solo al proceso propio.

Sheet 4 Gestion mensual
A1: IES | B1: Nivel de gestión mes a mes
B2: Cumplimiento real · se diligencia al cierre de cada mes
B4: CÓMO SE DILIGENCIA
B5: · Al cierre de cada mes, tomar de la aplicación el número de tareas completadas por persona.
B6: · Escribir ese número en las celdas de fondo amarillo. Las demás columnas se calculan solas.
B7: · La columna Programadas ya viene con el dato del mes correspondiente.
B9: ENERO
B10: Persona | C10: Programadas | D10: Completadas | E10: Cumplimiento | F10: Vencidas | G10: Observación
B11: Isnardi Sanches | C11: 6 | E11: =IFERROR(D11/C11,"")
B12: Luis Amador | C12: 10 | E12: =IFERROR(D12/C12,"")
B13: Cristian Bernal | C13: 15 | E13: =IFERROR(D13/C13,"")
B14: Beatriz | C14: 2 | E14: =IFERROR(D14/C14,"")
B15: Edgar Metaute | C15: 5 | E15: =IFERROR(D15/C15,"")
B16: Total equipo | C16: =SUM(C11:C15) | D16: =SUM(D11:D15) | E16: =IFERROR(D16/C16,"") | F16: =SUM(F11:F15)
B18: FEBRERO
B19: Persona | C19: Programadas | D19: Completadas | E19: Cumplimiento | F19: Vencidas | G19: Observación
B20: Isnardi Sanches | C20: 6 | E20: =IFERROR(D20/C20,"")
B21: Luis Amador | C21: 10 | E21: =IFERROR(D21/C21,"")
B22: Cristian Bernal | C22: 14 | E22: =IFERROR(D22/C22,"")
B23: Beatriz | C23: 2 | E23: =IFERROR(D23/C23,"")
B24: Edgar Metaute | C24: 5 | E24: =IFERROR(D24/C24,"")
B25: Total equipo | C25: =SUM(C20:C24) | D25: =SUM(D20:D24) | E25: =IFERROR(D25/C25,"") | F25: =SUM(F20:F24)
B27: MARZO
B28: Persona | C28: Programadas | D28: Completadas | E28: Cumplimiento | F28: Vencidas | G28: Observación
B29: Isnardi Sanches | C29: 6 | E29: =IFERROR(D29/C29,"")
B30: Luis Amador | C30: 10 | E30: =IFERROR(D30/C30,"")
B31: Cristian Bernal | C31: 15 | E31: =IFERROR(D31/C31,"")
B32: Beatriz | C32: 2 | E32: =IFERROR(D32/C32,"")
B33: Edgar Metaute | C33: 5 | E33: =IFERROR(D33/C33,"")
B34: Total equipo | C34: =SUM(C29:C33) | D34: =SUM(D29:D33) | E34: =IFERROR(D34/C34,"") | F34: =SUM(F29:F33)
B36: ABRIL
B37: Persona | C37: Programadas | D37: Completadas | E37: Cumplimiento | F37: Vencidas | G37: Observación
B38: Isnardi Sanches | C38: 6 | E38: =IFERROR(D38/C38,"")
B39: Luis Amador | C39: 10 | E39: =IFERROR(D39/C39,"")
B40: Cristian Bernal | C40: 14 | E40: =IFERROR(D40/C40,"")
B41: Beatriz | C41: 2 | E41: =IFERROR(D41/C41,"")
B42: Edgar Metaute | C42: 5 | E42: =IFERROR(D42/C42,"")
B43: Total equipo | C43: =SUM(C38:C42) | D43: =SUM(D38:D42) | E43: =IFERROR(D43/C43,"") | F43: =SUM(F38:F42)
B45: MAYO
B46: Persona | C46: Programadas | D46: Completadas | E46: Cumplimiento | F46: Vencidas | G46: Observación
...

Sheet 5 Consolidado
A1: IES | B1: Consolidado anual de cumplimiento
B2: Se alimenta automáticamente de la hoja 4 · no requiere diligenciamiento
B4: Mes | C4: Programadas | D4: Completadas | E4: Cumplimiento | F4: Vencidas
B5: Enero | C5: ='4 Gestion mensual'!C16 | D5: ='4 Gestion mensual'!D16 | E5: =IFERROR(D5/C5,"") | F5: ='4 Gestion mensual'!F16
B6: Febrero | C6: ='4 Gestion mensual'!C25 | D6: ='4 Gestion mensual'!D25 | E6: =IFERROR(D6/C6,"") | F6: ='4 Gestion mensual'!F25
B7: Marzo | C7: ='4 Gestion mensual'!C34 | D7: ='4 Gestion mensual'!D34 | E7: =IFERROR(D7/C7,"") | F7: ='4 Gestion mensual'!F34
B8: Abril | C8: ='4 Gestion mensual'!C43 | D8: ='4 Gestion mensual'!D43 | E8: =IFERROR(D8/C8,"") | F8: ='4 Gestion mensual'!F43
B9: Mayo | C9: ='4 Gestion mensual'!C52 | D9: ='4 Gestion mensual'!D52 | E9: =IFERROR(D9/C9,"") | F9: ='4 Gestion mensual'!F52
B10: Junio | C10: ='4 Gestion mensual'!C61 | D10: ='4 Gestion mensual'!D61 | E10: =IFERROR(D10/C10,"") | F10: ='4 Gestion mensual'!F61
B11: Julio | C11: ='4 Gestion mensual'!C70 | D11: ='4 Gestion mensual'!D70 | E11: =IFERROR(D11/C11,"") | F11: ='4 Gestion mensual'!F70
B12: Agosto | C12: ='4 Gestion mensual'!C79 | D12: ='4 Gestion mensual'!D79 | E12: =IFERROR(D12/C12,"") | F12: ='4 Gestion mensual'!F79
B13: Septiembre | C13: ='4 Gestion mensual'!C88 | D13: ='4 Gestion mensual'!D88 | E13: =IFERROR(D13/C13,"") | F13: ='4 Gestion mensual'!F88
B14: Octubre | C14: ='4 Gestion mensual'!C97 | D14: ='4 Gestion mensual'!D97 | E14: =IFERROR(D14/C14,"") | F14: ='4 Gestion mensual'!F97
B15: Noviembre | C15: ='4 Gestion mensual'!C106 | D15: ='4 Gestion mensual'!D106 | E15: =IFERROR(D15/C15,"") | F15: ='4 Gestion mensual'!F106
B16: Diciembre | C16: ='4 Gestion mensual'!C115 | D16: ='4 Gestion mensual'!D115 | E16: =IFERROR(D16/C16,"") | F16: ='4 Gestion mensual'!F115
B17: TOTAL AÑO | C17: =SUM(C5:C16) | D17: =SUM(D5:D16) | E17: =IFERROR(D17/C17,"") | F17: =SUM(F5:F16)
B20: Las celdas de esta hoja se calculan solas. Para que muestren datos, diligencie primero la hoja 4.
